Workbook

Sheet Hardware
A1: Hardware and software resources of the author's machine
A2: Surveyed on 22 Oct 2026 and updated on 23 Oct 2026 with the Ollama measurements. 'User screenshot' = a screenshot taken on the author's machine; the other items cite their source in column D.
A4: Category | B4: Item | C4: Specification | D4: Source / note
A5: Machine | B5: Equipment | C5: Dell 24 All-in-One EC24250, Windows 11 Home Single Language, 64-bit, version 26H2 (build 26300.9711) | D5: User screenshot (System > About)
A6: CPU | B6: Model | C6: 13th Gen Intel Core i5-1334U | D6: User screenshot
A7: CPU | B7: Cores / threads | C7: 10 cores (2 performance + 8 efficiency), 12 logical processors | D7: Total 10/12: user screenshot. 2P+8E split: eatyourbytes.com and pchardware.org
A8: CPU | B8: Frequency | C8: Base 1.30 GHz; turbo up to 4.60 GHz; 3.52 GHz at the time of the 22 Oct screenshot | D8: Base and 3.52 GHz: user screenshot. Turbo: eatyourbytes.com (Intel specification)
A9: CPU | B9: Base power | C9: 15 W | D9: eatyourbytes.com (Intel specification)
A10: CPU | B10: Cache | C10: L1 928 KB; L2 6.5 MB; L3 12.0 MB | D10: User screenshot (Task Manager > CPU)
A11: CPU | B11: Virtualization | C11: Enabled | D11: User screenshot
A12: RAM | B12: Capacity | C12: 16.0 GB installed (15.7 GB usable) | D12: User screenshot
A13: RAM | B13: Type and speed | C13: SODIMM, 5200 MT/s | D13: User screenshot (Task Manager > Memory)
A14: RAM | B14: Channels | C14: 1 of 2 slots used: single channel | D14: User screenshot. Single-channel conclusion: inferred from 1 module in use (the CPU supports 2 channels)
A15: GPU | B15: Model | C15: Intel UHD Graphics, 128 MB dedicated | D15: User screenshot. Intel lists the i5-1334U with Iris Xe only as 'eligible' (pchardware.org); Windows showing UHD is consistent with single channel (inference)
... A24: State on 23 Oct | B24: Free RAM before the measurement | C24: 4.2 GB (measured twice before run 1, with Win32_OperatingSystem.FreePhysicalMemory) | D24: User screenshot (terminal). Not measured before the other runs or during any run

Sheet Limitations
A1: What the hardware limits in the SlothGuard project (updated on 23 Oct 2026)
A2: Column F separates what was measured from what is an estimate. The mitigations are suggestions; the 'think=false' one was measured (Measurements tab), the others were not tested.
A4: # | B4: Limitation | C4: Cause | D4: Practical consequence | E4: Mitigation | F4: Nature of the information | G4: Source
A5: 1 | B5: Generation speed | C5: Single-channel memory: about 41.6 GB/s (calculation in the Calculations tab) versus 83.2 GB/s in dual channel; 15 W CPU. | D5: Measured: 13.00 to 21.56 tokens/s with gemma4:e2b in 6 runs. The earlier theoretical estimate (about 14 tokens/s) was exceeded, that is, the hypothesis was wrong. | E5: Short prompts, batch generation, caching of the explanations, think=false. | F5: Measured (6 runs, 1 machine); cause of the variation not measured | G5: Measurements tab; terminal screenshots of 23 Oct 2026
A6: 2 | B6: Model size | C6: 15.7 GB of usable RAM, shared with Windows and other programs. | D6: E2B (4.6 GB on disk) ran with 4.2 GB of free RAM before the measurement. E4B and 12B were not tested. 26B and 31B are out: the quantized weights of the 31B (17.5 GB, third-party figure) exceed the usable RAM. | E6: Use gemma4:e2b. Test the E4B only if time allows. | F6: E2B: measured. E4B and 12B: not tested. 31B: calculation from a third-party source | G6: Terminal screenshot; jacar.es; ai.google.dev/gemma/docs/core
A7: 3 | B7: No dedicated GPU | C7: Intel UHD with 128 MB dedicated; no CUDA. Ollama's support for Intel GPUs via Vulkan is experimental. | D7: The measurements were made with the default Ollama configuration; we did not verify whether the integrated GPU was used. Local fine-tuning is not feasible. | E7: Vulkan only as an optional test; fine-tuning out of scope. | F7: Sources checked; iGPU use not tested | G7: dasroot.net; ggml-org/llama.cpp issue 19327; ai.google.dev/gemma/docs/core
A8: 4 | B8: Low-power CPU | C8: 15 W chip (base). | D8: Speed varied from 13.00 to 21.56 tokens/s between runs. Power and temperature are hypotheses for the variation, not measured. | E8: Measure sustained speed in a complete report; 'Best performance' power mode. | F8: Variation measured; cause not measured | G8: Measurements tab
A9: 5 | B9: Simultaneous use and occupied RAM | C9: On 22 Oct: 14.2 GB in use and 1.5 GB free. On 23 Oct: 4.2 GB free before the measurement. | D9: The model ran in all 6 runs with 4.2 GB free, below the 6 GB margin that had been suggested; RAM was not measured during the runs. Running Ollama, the app and a browser together remains risky. | E9: Close heavy programs and restart Windows before tests and before recording the video. | F9: RAM before: measured. During: not measured. 6 GB target: working hypothesis | G9: Memory screenshots (22 Oct) and terminal (23 Oct)
A10: 6 | B10: Thinking on by default | C10: gemma4 generates a reasoning draft before the answer, and Ollama's documentation says this comes enabled by default. | D10: Measured: with thinking on, ~506 tokens per answer and ~27.1 s (warm runs); off, ~94 tokens and ~6.2 s. Gain of ~4.3x, at the same speed per token. | E10: think=false in the CLI (--think=false) and in the API's think field; the final text is kept separate from the reasoning, according to the documentation. | F10: Measured (3 runs per mode) | G10: Measurements tab; docs.ollama.com/capabilities/thinking
A11: 7 | B11: Quality of the model's text | C11: Small model (E2B) with a one-instruction prompt. | D11: The word 'critical' appeared in 4 of 6 answers, although the severity was 'high'. One answer had 5 sentences despite the limit of 4. | E11: Severity always comes from the rules, never from the model. Validate the number of sentences and use the fallback text (to be implemented, tests first). | F11: Observed in 6 answers (small sample) | G11: Terminal screenshots of 23 Oct 2026
A13: What remains feasible
B14: SlothGuard as designed, with think=false: SoD rules in code, local E2B model explaining one finding at a time, batch generation, report assembled by code. For 8 findings the estimate is about 54 to 73 s (Calculations tab; an estimate made from 3 runs, not a measurement of the whole report). Running on ordinary equipment, without a dedicated GPU, strengthens the challenge's argument about accessible open AI.

Sheet Measurements
A1: Ollama measurements (gemma4:e2b), 23 Oct 2026
A2: Source: terminal screenshots provided by the author (ollama 0.40.8, --verbose output). Blue = value copied from the screenshot; black = formula. Missing 'cache' in the cold run was treated as 0.
A4: Mode | B4: Run | C4: Load (s) | D4: Prompt tokens | E4: Cached tokens | F4: Generated tokens | G4: Generation duration (s) | H4: Reported rate (tok/s) | I4: Recalculated rate (tok/s) | J4: Total (s)
A5: Thinking on | B5: 1 (cold) | C5: 15.46347 | D5: 109 | E5: 0 | F5: 508 | G5: 29.996968 | H5: 16.94 | I5: =F5/G5 -> 16.935045 | J5: 46.89358
A6: Thinking on | B6: 2 | C6: 0.0187864 | D6: 109 | E6: 104 | F6: 521 | G6: 26.825821 | H6: 19.42 | I6: =F6/G6 -> 19.421586 | J6: 26.982313
A7: Thinking on | B7: 3 | C7: 0.0313595 | D7: 109 | E7: 104 | F7: 489 | G7: 27.014688 | H7: 18.1 | I7: =F7/G7 -> 18.101264 | J7: 27.179436
A8: Thinking off (--think=false) | B8: 1 (cold) | C8: 13.983434 | D8: 102 | E8: 0 | F8: 84 | G8: 4.196442 | H8: 20.02 | I8: =F8/G8 -> 20.016957 | J8: 19.393576
A9: Thinking off (--think=false) | B9: 2 | C9: 0.011259 | D9: 102 | E9: 97 | F9: 102 | G9: 4.731158 | H9: 21.56 | I9: =F9/G9 -> 21.559204 | J9: 4.8751631
A10: Thinking off (--think=false) | B10: 3 | C10: 0.008227 | D10: 102 | E10: 97 | F10: 97 | G10: 7.459571 | H10: 13 | I10: =F10/G10 -> 13.003429 | J10: 7.6035057
A12: Recalculated rate = generated tokens / generation duration; it matches the rate reported by Ollama.
A13: In runs 2 and 3 of each mode, almost the whole prompt came from the cache (104 of 109 and 97 of 102 tokens), so the prompt-reading rate of those runs is not comparable to that of run 1 and is not in this table.
A14: Conditions: free RAM before run 1 of 23 Oct = 4.2 GB; power mode and open programs were not recorded; RAM during the runs was not measured.

Sheet Calculations
A1: Supporting calculations
A2: Legend: blue = input (screenshot, cited source or hypothesis); black = formula; green = formula that reads the Measurements tab; yellow fill = working hypothesis, editable.
A4: Parameter | B4: Value | C4: Unit | D4: Source / note
A5: 1. Memory bandwidth (single vs dual channel)
A6: RAM transfer rate | B6: 5200 | C6: MT/s | D6: User screenshot (Task Manager > Memory)
A7: Bus width per channel | B7: 8 | C7: bytes | D7: 64 bits per channel (eatyourbytes.com cites 2 x 64 bits for the CPU)
A8: Channels in use | B8: 1 | C8: channels | D8: User screenshot: 1 of 2 slots used
A9: Channels supported by the CPU | B9: 2 | C9: channels | D9: eatyourbytes.com (Intel specification)
A10: Current bandwidth (channels in use) | B10: =B6*B7*B8/1000 -> 41.6 | C10: GB/s | D10: MT/s x bytes x channels / 1000. Theoretical peak value
A11: Maximum CPU bandwidth (two channels) | B11: =B6*B7*B9/1000 -> 83.2 | C11: GB/s | D11: Matches the 83.2 GB/s from eatyourbytes.com
A12: Bandwidth loss versus the maximum | B12: =1-B10/B11 -> 0.5 | C12: % | D12: Effect of using a single memory module
A13: 2. Summary of the Ollama measurements (gemma4:e2b; data in the Measurements tab)
A14: Tokens generated per answer, thinking on (average) | B14: =AVERAGE(Measurements!F5:F7) -> 506 | C14: tokens | D14: Average of the 3 runs
A15: Tokens generated per answer, thinking off (average) | B15: =AVERAGE(Measurements!F8:F10) -> 94.333333 | C15: tokens | D15: Average of the 3 runs with --think=false
A16: Reduction in generated tokens | B16: =1-B15/B14 -> 0.81357049 | C16: % | D16: How much of what the model generated was reasoning draft, on average
A17: Generation speed, thinking on (average) | B17: =AVERAGE(Measurements!H5:H7) -> 18.153333 | C17: tokens/s | D17: Rate reported by Ollama
A18: Generation speed, thinking off (average) | B18: =AVERAGE(Measurements!H8:H10) -> 18.193333 | C18: tokens/s | D18: Speed per token is practically the same in both modes
A19: Minimum speed across the 6 runs | B19: =MIN(Measurements!H5:H10) -> 13 | C19: tokens/s | D19: Cause of the variation not measured
A20: Maximum speed across the 6 runs | B20: =MAX(Measurements!H5:H10) -> 21.56 | C20: tokens/s | D20: Use the minimum-to-maximum range in the post, not just the best number
A21: Total time, runs 2 and 3, thinking on (average) | B21: =AVERAGE(Measurements!J6:J7) -> 27.080874 | C21: s | D21: 'Warm' runs (model already loaded)
A22: Total time, runs 2 and 3, thinking off (average) | B22: =AVERAGE(Measurements!J9:J10) -> 6.2393344 | C22: s | D22: 'Warm' runs
A23: Speed gain (total time) from turning thinking off | B23: =B21/B22 -> 4.3403467 | C23: x | D23: Time on / time off
A24: Total time of the cold run, thinking on | B24: =Measurements!J5 -> 46.89358 | C24: s | D24: Includes loading the model
A25: Total time of the cold run, thinking off | B25: =Measurements!J8 -> 19.393576 | C25: s | D25: Includes loading the model
A26: Number of findings in the report | B26: 8 | C26: findings | D26: Same number of findings that the synthetic set produced in a verification run (5 high, 2 medium and 1 low)
A27: Report estimate, thinking on | B27: =B24+(B26-1)*B21 -> 236.4597 | C27: s | D27: ESTIMATE, not an end-to-end measurement: cold run + (N-1) warm runs, assuming prompts of the same size
A28: in minutes | B28: =B27/60 -> 3.940995 | C28: min
A29: Report estimate, thinking off | B29: =B25+(B26-1)*B22 -> 63.068917 | C29: s | D29: ESTIMATE, same calculation
A30: optimistic scenario (fastest warm run) | B30: =B25+(B26-1)*MIN(Measurements!J9:J10) -> 53.519718 | C30: s | D30: ESTIMATE
A31: pessimistic scenario (slowest warm run) | B31: =B25+(B26-1)*MAX(Measurements!J9:J10) -> 72.618116 | C31: s | D31: ESTIMATE
A32: 3. Earlier speed-ceiling hypothesis (REFUTED by the measurement)
A33: Quantized weights of Gemma 4 E2B (4-bit), according to a third-party source | B33: 2.9 | C33: GB | D33: jacar.es, which cites Google's table (not checked directly). The file in Ollama is 4.6 GB (ollama list)
A34: Quantized weights of Gemma 4 31B (4-bit) | B34: 17.5 | C34: GB | D34: jacar.es, which cites Google's table (not checked directly)
A35: Old ceiling (current bandwidth / E2B weights) | B35: =B10/B33 -> 14.344828 | C35: tokens/s | D35: Working hypothesis that the model reads all the weights for each token
A36: Measured (thinking off) / old ceiling | B36: =B18/B35 -> 1.2682853 | C36: x | D36: Above 1 = the measured speed exceeded the ceiling
A37: Hypothesis refuted (measured above the ceiling)? | B37: =IF(B18>B35,"Yes","No") -> Yes | C37: — | D37: The model does not read all the weights for each token; the exact reason is unknown (hypothesis: the E2B's 'effective' parameters)
A38: 4. RAM budget
A39: Installed physical RAM | B39: 16 | C39: GB | D39: User screenshot (System > About)
A40: Usable RAM | B40: 15.7 | C40: GB | D40: User screenshot (System > About)
A41: RAM in use in the 22 Oct screenshot | B41: 14.2 | C41: GB | D41: User screenshot (Task Manager > Memory)
...

Sheet Sources
A1: Sources consulted
A3: Source | B3: Address | C3: Used for
A4: Windows and terminal screenshots provided by the author | B4: System > About; Task Manager (GPU, Memory, CPU), 22 Oct 2026; terminal with ollama, 23 Oct 2026 | C4: All measured data of the machine and of Ollama
A5: eatyourbytes.com: Intel Core i5-1334U | B5: https://www.eatyourbytes.com/cpu-detail/intel-i5-1334u/ | C5: 10 cores (2P+8E), 12 threads, 15 W, turbo 4.6 GHz, 2 channels, 83.2 GB/s
A6: pchardware.org: Intel Core i5-1334U | B6: https://pchardware.org/processors/intel-core-i5-1334u/ | C6: 2P+8E split; Iris Xe graphics only as 'eligible'
A7: jacar.es: Gemma 4 locally with Ollama | B7: https://jacar.es/en/gemma-4-locally-with-ollama/ | C7: Quantized weights from 2.9 GB (E2B) to 17.5 GB (31B), citing Google's table
A8: Google AI for Developers: Gemma 4 | B8: https://ai.google.dev/gemma/docs/core | C8: Gemma 4 sizes and higher memory use in fine-tuning
A9: Ollama documentation: Thinking | B9: https://docs.ollama.com/capabilities/thinking | C9: Thinking enabled by default; --think=false in the CLI and think field in the API
A10: Ollama documentation: Windows | B10: https://docs.ollama.com/windows | C10: Installation on Windows; background execution; API on localhost:11434
A11: dasroot.net: Ollama performance tuning | B11: https://dasroot.net/posts/2026/01/ollama-performance-tuning-gpu-acceleration-model-quantization/ | C11: Experimental Vulkan support (OLLAMA_VULKAN=1)
A12: GitHub ggml-org/llama.cpp, issue 19327 | B12: https://github.com/ggml-org/llama.cpp/issues/19327 | C12: Report of corrupted output on Intel iGPU via Vulkan
