Workbook

Sheet Hardware
A1: Recursos de hardware e software do usuário
A2: Levantados em 22/10/2026 e atualizados em 23/10/2026 com as medições do Ollama. 'Print do usuário' = captura de tela enviada na conversa; os demais itens citam a fonte na coluna D.
A4: Categoria | B4: Item | C4: Especificação | D4: Origem / observação
A5: Máquina | B5: Equipamento | C5: Dell 24 All-in-One EC24250, Windows 11 Home Single Language, 64 bits, versão 26H2 (compilação 26300.9711) | D5: Print do usuário (Sistema > Sobre)
A6: CPU | B6: Modelo | C6: 13th Gen Intel Core i5-1334U | D6: Print do usuário
A7: CPU | B7: Núcleos / threads | C7: 10 núcleos (2 de desempenho + 8 de eficiência), 12 processadores lógicos | D7: Total 10/12: print do usuário. Divisão 2P+8E: eatyourbytes.com e pchardware.org
A8: CPU | B8: Frequência | C8: Base 1,30 GHz; turbo até 4,60 GHz; 3,52 GHz no momento do print de 22/10 | D8: Base e 3,52 GHz: print do usuário. Turbo: eatyourbytes.com (especificação Intel)
A9: CPU | B9: Consumo base | C9: 15 W | D9: eatyourbytes.com (especificação Intel)
A10: CPU | B10: Cache | C10: L1 928 KB; L2 6,5 MB; L3 12,0 MB | D10: Print do usuário (Gerenciador de Tarefas > CPU)
A11: CPU | B11: Virtualização | C11: Habilitada | D11: Print do usuário
A12: RAM | B12: Capacidade | C12: 16,0 GB instalados (15,7 GB utilizáveis) | D12: Print do usuário
A13: RAM | B13: Tipo e velocidade | C13: SODIMM, 5200 MT/s | D13: Print do usuário (Gerenciador de Tarefas > Memória)
A14: RAM | B14: Canais | C14: 1 de 2 slots usados: canal único | D14: Print do usuário. Conclusão de canal único: inferida de 1 módulo em uso (a CPU suporta 2 canais)
A15: GPU | B15: Modelo | C15: Intel UHD Graphics, 128 MB dedicados | D15: Print do usuário. A Intel lista o i5-1334U com Iris Xe apenas como 'elegível' (pchardware.org); o Windows mostrar UHD é compatível com canal único (inferência)
... A24: Estado em 23/10 | B24: RAM livre antes da medição | C24: 4,2 GB (medida duas vezes antes da execução 1, com Win32_OperatingSystem.FreePhysicalMemory) | D24: Print do usuário (terminal). Não medida antes das outras execuções nem durante nenhuma

Sheet Limitações
A1: O que o hardware limita no projeto SlothGuard (atualizado em 23/10/2026)
A2: A coluna F separa o que foi medido do que é estimativa. As mitigações são sugestões; a de 'think=false' foi medida (aba Medições), as demais não foram testadas.
A4: # | B4: Limitação | C4: Causa | D4: Consequência prática | E4: Mitigação | F4: Natureza da informação | G4: Fonte
A5: 1 | B5: Velocidade de geração | C5: Memória em canal único: cerca de 41,6 GB/s (cálculo na aba Cálculos) contra 83,2 GB/s em dois canais; CPU de 15 W. | D5: Medido: 13,00 a 21,56 tokens/s no gemma4:e2b em 6 execuções. A estimativa teórica anterior (cerca de 14 tokens/s) foi superada, ou seja, a hipótese estava errada. | E5: Prompts curtos, geração em lote, cache das explicações, think=false. | F5: Medido (6 execuções, 1 máquina); causa da variação não medida | G5: Aba Medições; prints do terminal de 23/10/2026
A6: 2 | B6: Tamanho do modelo | C6: 15,7 GB de RAM utilizável, compartilhados com Windows e programas. | D6: E2B (4,6 GB em disco) rodou com 4,2 GB de RAM livre antes da medição. E4B e 12B não foram testados. 26B e 31B ficam fora: os pesos quantizados do 31B (17,5 GB, valor de terceiros) superam a RAM utilizável. | E6: Usar gemma4:e2b. Testar o E4B só se sobrar tempo. | F6: E2B: medido. E4B e 12B: não testados. 31B: cálculo a partir de fonte de terceiros | G6: Print do terminal; jacar.es; ai.google.dev/gemma/docs/core
A7: 3 | B7: Sem GPU dedicada | C7: Intel UHD com 128 MB dedicados; sem CUDA. Suporte do Ollama a GPU Intel via Vulkan é experimental. | D7: As medições foram feitas na configuração padrão do Ollama; não verificamos se a GPU integrada foi usada. Fine-tuning local é inviável. | E7: Vulkan só como teste opcional; fine-tuning fora do escopo. | F7: Fontes verificadas; uso da iGPU não testado | G7: dasroot.net; ggml-org/llama.cpp issue 19327; ai.google.dev/gemma/docs/core
A8: 4 | B8: CPU de baixo consumo | C8: Chip de 15 W (base). | D8: A velocidade variou de 13,00 a 21,56 tokens/s entre execuções. Energia e temperatura são hipóteses para a variação, não medidas. | E8: Medir a velocidade sustentada em um relatório completo; modo de energia 'Melhor desempenho'. | F8: Variação medida; causa não medida | G8: Aba Medições
A9: 5 | B9: Uso simultâneo e RAM ocupada | C9: Em 22/10: 14,2 GB em uso e 1,5 GB livres. Em 23/10: 4,2 GB livres antes da medição. | D9: O modelo rodou nas 6 execuções com 4,2 GB livres, abaixo da margem de 6 GB que sugeri; a RAM não foi medida durante as execuções. Rodar Ollama, app, navegador e Kaggle juntos continua arriscado. | E9: Fechar programas pesados e reiniciar o Windows antes de testes e da gravação do vídeo. | F9: RAM antes: medida. Durante: não medida. Meta de 6 GB: hipótese minha | G9: Prints de Memória (22/10) e do terminal (23/10)
A10: 6 | B10: Raciocínio (thinking) ligado por padrão | C10: O gemma4 gera um rascunho de raciocínio antes da resposta, e a documentação do Ollama diz que isso vem ativado por padrão. | D10: Medido: com o raciocínio ligado foram ~506 tokens por resposta e ~27,1 s (execuções mornas); desligado, ~94 tokens e ~6,2 s. Ganho de ~4,3x, com a mesma velocidade por token. | E10: think=false na CLI (--think=false) e no campo think da API; o texto final fica separado do raciocínio, segundo a documentação. | F10: Medido (3 execuções por modo) | G10: Aba Medições; docs.ollama.com/capabilities/thinking
A11: 7 | B11: Qualidade do texto do modelo | C11: Modelo pequeno (E2B) com prompt de uma instrução. | D11: A palavra 'critical' apareceu em 4 de 6 respostas, embora a gravidade fosse 'high'. Uma resposta teve 5 frases apesar do limite de 4. | E11: Gravidade vem sempre das regras, nunca do modelo. Validar o número de frases e usar o texto de reserva (a ser implementado, com testes primeiro). | F11: Observado em 6 respostas (amostra pequena) | G11: Prints do terminal de 23/10/2026
A13: O que continua viável
B14: SlothGuard como desenhado, com think=false: regras SoD em código, modelo local E2B explicando um achado por vez, geração em lote, relatório montado por código. Para 8 achados a estimativa é de cerca de 54 a 73 s (aba Cálculos; estimativa feita com 3 execuções, não é uma medição do relatório inteiro). Rodar em equipamento comum, sem GPU dedicada, reforça o argumento do desafio sobre IA aberta acessível.
A16: Pendências
B17: Confirmar em qual formato estão os pesos do Gemma 4 baixados do Kaggle (Keras, Transformers ou GGUF) e quais tamanhos você tem.
B18: T04b: usuário de teste no Auth0 com push cadastrado no app Guardian (fica para 23/10).
B19: Opcional: medir o gemma4:e4b na mesma tabela, se sobrar tempo e RAM.
B20: Opcional: medir um relatório completo de 8 achados ponta a ponta, quando o código existir.

Sheet Medições
A1: Medições do Ollama (gemma4:e2b), 23/10/2026
A2: Origem: prints do terminal enviados pelo usuário (ollama 0.40.8, saída do --verbose). Azul = valor copiado do print; preto = fórmula. 'Cache' ausente na execução fria foi tratado como 0.
A4: Modo | B4: Execução | C4: Carga (s) | D4: Tokens do prompt | E4: Tokens em cache | F4: Tokens gerados | G4: Duração da geração (s) | H4: Taxa informada (tok/s) | I4: Taxa recalculada (tok/s) | J4: Total (s)
A5: Raciocínio ligado | B5: 1 (fria) | C5: 15.46347 | D5: 109 | E5: 0 | F5: 508 | G5: 29.996968 | H5: 16.94 | I5: =F5/G5 -> 16.935045 | J5: 46.89358
A6: Raciocínio ligado | B6: 2 | C6: 0.0187864 | D6: 109 | E6: 104 | F6: 521 | G6: 26.825821 | H6: 19.42 | I6: =F6/G6 -> 19.421586 | J6: 26.982313
A7: Raciocínio ligado | B7: 3 | C7: 0.0313595 | D7: 109 | E7: 104 | F7: 489 | G7: 27.014688 | H7: 18.1 | I7: =F7/G7 -> 18.101264 | J7: 27.179436
A8: Raciocínio desligado (--think=false) | B8: 1 (fria) | C8: 13.983434 | D8: 102 | E8: 0 | F8: 84 | G8: 4.196442 | H8: 20.02 | I8: =F8/G8 -> 20.016957 | J8: 19.393576
A9: Raciocínio desligado (--think=false) | B9: 2 | C9: 0.011259 | D9: 102 | E9: 97 | F9: 102 | G9: 4.731158 | H9: 21.56 | I9: =F9/G9 -> 21.559204 | J9: 4.8751631
A10: Raciocínio desligado (--think=false) | B10: 3 | C10: 0.008227 | D10: 102 | E10: 97 | F10: 97 | G10: 7.459571 | H10: 13 | I10: =F10/G10 -> 13.003429 | J10: 7.6035057
A12: Taxa recalculada = tokens gerados / duração da geração; confere com a taxa informada pelo Ollama.
A13: Nas execuções 2 e 3 de cada modo, quase todo o prompt veio do cache (104 de 109 e 97 de 102 tokens), por isso a taxa de leitura do prompt dessas execuções não é comparável à da execução 1 e não consta nesta tabela.
A14: Condições: RAM livre antes da execução 1 de 23/10 = 4,2 GB; modo de energia e programas abertos não foram registrados; a RAM durante as execuções não foi medida.

Sheet Cálculos
A1: Cálculos de apoio
A2: Legenda: azul = entrada (print, fonte citada ou hipótese); preto = fórmula; verde = fórmula que lê a aba Medições; fundo amarelo = hipótese minha, editável.
A4: Parâmetro | B4: Valor | C4: Unidade | D4: Origem / observação
A5: 1. Banda de memória (canal único x duplo)
A6: Taxa de transferência da RAM | B6: 5200 | C6: MT/s | D6: Print do usuário (Gerenciador de Tarefas > Memória)
A7: Largura do barramento por canal | B7: 8 | C7: bytes | D7: 64 bits por canal (eatyourbytes.com cita 2 x 64 bits para a CPU)
A8: Canais em uso | B8: 1 | C8: canais | D8: Print do usuário: 1 de 2 slots usados
A9: Canais suportados pela CPU | B9: 2 | C9: canais | D9: eatyourbytes.com (especificação Intel)
A10: Banda atual (canais em uso) | B10: =B6*B7*B8/1000 -> 41.6 | C10: GB/s | D10: MT/s x bytes x canais / 1000. Valor teórico de pico
A11: Banda máxima da CPU (dois canais) | B11: =B6*B7*B9/1000 -> 83.2 | C11: GB/s | D11: Confere com os 83,2 GB/s de eatyourbytes.com
A12: Perda de banda frente ao máximo | B12: =1-B10/B11 -> 0.5 | C12: % | D12: Efeito de usar um único módulo de memória
A13: 2. Resumo das medições do Ollama (gemma4:e2b; dados na aba Medições)
A14: Tokens gerados por resposta, raciocínio ligado (média) | B14: =AVERAGE(Medições!F5:F7) -> 506 | C14: tokens | D14: Média das 3 execuções
A15: Tokens gerados por resposta, raciocínio desligado (média) | B15: =AVERAGE(Medições!F8:F10) -> 94.333333 | C15: tokens | D15: Média das 3 execuções com --think=false
A16: Redução de tokens gerados | B16: =1-B15/B14 -> 0.81357049 | C16: % | D16: Quanto do que o modelo gerava era rascunho de raciocínio, em média
A17: Velocidade de geração, raciocínio ligado (média) | B17: =AVERAGE(Medições!H5:H7) -> 18.153333 | C17: tokens/s | D17: Taxa informada pelo Ollama
A18: Velocidade de geração, raciocínio desligado (média) | B18: =AVERAGE(Medições!H8:H10) -> 18.193333 | C18: tokens/s | D18: A velocidade por token é praticamente a mesma nos dois modos
A19: Velocidade mínima nas 6 execuções | B19: =MIN(Medições!H5:H10) -> 13 | C19: tokens/s | D19: Causa da variação não medida
A20: Velocidade máxima nas 6 execuções | B20: =MAX(Medições!H5:H10) -> 21.56 | C20: tokens/s | D20: Use a faixa mínimo a máximo no post, não só o melhor número
A21: Tempo total, execuções 2 e 3, raciocínio ligado (média) | B21: =AVERAGE(Medições!J6:J7) -> 27.080874 | C21: s | D21: Execuções 'mornas' (modelo já carregado)
A22: Tempo total, execuções 2 e 3, raciocínio desligado (média) | B22: =AVERAGE(Medições!J9:J10) -> 6.2393344 | C22: s | D22: Execuções 'mornas'
A23: Ganho de velocidade (tempo total) ao desligar o raciocínio | B23: =B21/B22 -> 4.3403467 | C23: x | D23: Tempo ligado / tempo desligado
A24: Tempo total da execução fria, raciocínio ligado | B24: =Medições!J5 -> 46.89358 | C24: s | D24: Inclui o carregamento do modelo
A25: Tempo total da execução fria, raciocínio desligado | B25: =Medições!J8 -> 19.393576 | C25: s | D25: Inclui o carregamento do modelo
A26: Número de achados do relatório | B26: 8 | C26: achados | D26: Mesmo número de achados que o conjunto sintético gerou em uma execução de verificação (5 high, 2 medium e 1 low)
A27: Estimativa do relatório, raciocínio ligado | B27: =B24+(B26-1)*B21 -> 236.4597 | C27: s | D27: ESTIMATIVA, não medição ponta a ponta: execução fria + (N-1) execuções mornas, supondo prompts do mesmo tamanho
A28: em minutos | B28: =B27/60 -> 3.940995 | C28: min
A29: Estimativa do relatório, raciocínio desligado | B29: =B25+(B26-1)*B22 -> 63.068917 | C29: s | D29: ESTIMATIVA, mesma conta
A30: cenário otimista (execução morna mais rápida) | B30: =B25+(B26-1)*MIN(Medições!J9:J10) -> 53.519718 | C30: s | D30: ESTIMATIVA
A31: cenário pessimista (execução morna mais lenta) | B31: =B25+(B26-1)*MAX(Medições!J9:J10) -> 72.618116 | C31: s | D31: ESTIMATIVA
A32: 3. Hipótese anterior de teto de velocidade (REFUTADA pela medição)
A33: Pesos do Gemma 4 E2B quantizado (4 bits), segundo fonte de terceiros | B33: 2.9 | C33: GB | D33: jacar.es, que cita a tabela do Google (não conferida diretamente). O arquivo no Ollama tem 4,6 GB (ollama list)
A34: Pesos do Gemma 4 31B quantizado (4 bits) | B34: 17.5 | C34: GB | D34: jacar.es, que cita a tabela do Google (não conferida diretamente)
A35: Teto antigo (banda atual / pesos do E2B) | B35: =B10/B33 -> 14.344828 | C35: tokens/s | D35: Hipótese minha de que o modelo lê todos os pesos a cada token
A36: Medido (raciocínio desligado) / teto antigo | B36: =B18/B35 -> 1.2682853 | C36: x | D36: Acima de 1 = a velocidade medida passou o teto
A37: Hipótese refutada (medido acima do teto)? | B37: =IF(B18>B35,"Sim","Não") -> Sim | C37: — | D37: O modelo não lê todos os pesos a cada token; o motivo exato é desconhecido (hipótese: parâmetros 'efetivos' do E2B)
A38: 4. Orçamento de RAM
A39: RAM física instalada | B39: 16 | C39: GB | D39: Print do usuário (Sistema > Sobre)
A40: RAM utilizável | B40: 15.7 | C40: GB | D40: Print do usuário (Sistema > Sobre)
A41: RAM em uso no print de 22/10 | B41: 14.2 | C41: GB | D41: Print do usuário (Gerenciador de Tarefas > Memória)
...

Sheet Fontes
A1: Fontes consultadas
A3: Fonte | B3: Endereço | C3: Usada para
A4: Capturas de tela do Windows e do terminal enviadas pelo usuário | B4: Sistema > Sobre; Gerenciador de Tarefas (GPU, Memória, CPU), 22/10/2026; terminal com ollama, 23/10/2026 | C4: Todos os dados medidos da máquina e do Ollama
A5: eatyourbytes.com: Intel Core i5-1334U | B5: https://www.eatyourbytes.com/cpu-detail/intel-i5-1334u/ | C5: 10 núcleos (2P+8E), 12 threads, 15 W, turbo 4,6 GHz, 2 canais, 83,2 GB/s
A6: pchardware.org: Intel Core i5-1334U | B6: https://pchardware.org/processors/intel-core-i5-1334u/ | C6: Divisão 2P+8E; gráficos Iris Xe apenas como 'elegível'
A7: jacar.es: Gemma 4 locally with Ollama | B7: https://jacar.es/en/gemma-4-locally-with-ollama/ | C7: Pesos quantizados de 2,9 GB (E2B) a 17,5 GB (31B), citando a tabela do Google
A8: Google AI for Developers: Gemma 4 | B8: https://ai.google.dev/gemma/docs/core | C8: Tamanhos do Gemma 4 e maior consumo de memória no fine-tuning
A9: Documentação do Ollama: Thinking | B9: https://docs.ollama.com/capabilities/thinking | C9: Raciocínio ativado por padrão; --think=false na CLI e campo think na API
A10: Documentação do Ollama: Windows | B10: https://docs.ollama.com/windows | C10: Instalação no Windows; execução em segundo plano; API em localhost:11434
A11: dasroot.net: Ollama performance tuning | B11: https://dasroot.net/posts/2026/01/ollama-performance-tuning-gpu-acceleration-model-quantization/ | C11: Suporte experimental a Vulkan (OLLAMA_VULKAN=1)
A12: GitHub ggml-org/llama.cpp, issue 19327 | B12: https://github.com/ggml-org/llama.cpp/issues/19327 | C12: Relato de saída corrompida em iGPU Intel via Vulkan
